Workbook

Sheet Income Statement
B1: 2025 (€000) | C1: 2024 (€000) | D1: 2023 (€000)
A2: Net revenues | B2: 7145768 | C2: 6676668 | D2: 5970146
A3: Cost of sales | B3: 3452971 | C3: 3329483 | D3: 2995877
A4: Selling, general and administrative costs | B4: 642490 | C4: 561144 | D4: 462580
A5: Research and development costs | B5: 918861 | C5: 894092 | D5: 881559
A6: Other expenses, net | B6: 34302 | C6: 12443 | D6: 18898
A7: Result from investments | B7: 12572 | C7: 8245 | D7: 6137
A8: Operating profit (EBIT) | B8: 2109716 | C8: 1887751 | D8: 1617369
A9: Financial income | B9: 168145 | C9: 147100 | D9: 132319
A10: Financial expenses | B10: 214226 | C10: 145895 | D10: 147334
A11: Financial expenses/(income), net | B11: 46081 | C11: -1205 | D11: 15015
A12: Profit before taxes | B12: 2063635 | C12: 1888956 | D12: 1602354
A13: Interest expense | B13: 41168 | C13: 40054 | D13: 29258
... A19: Diluted earnings per common share (in €) | B19: 8.96 | C19: 8.46 | D19: 6.9

Sheet Comprehensive Income
B1: 2025 (€000) | C1: 2024 (€000) | D1: 2023 (€000)
A2: Net profit | B2: 1599516 | C2: 1525913 | D2: 1257457
A3: Gains /(Losses) on remeasurement of defined benefit plans | B3: 135 | C3: -691 | D3: 221
A4: Related tax impact | B4: -30 | C4: 168 | D4: -52
A5: Total items not reclassified to income statement | B5: 105 | C5: -523 | D5: 169
A6: Gains/(Losses) on cash flow hedging instruments | B6: 120314 | C6: -86810 | D6: -26284
A7: Exchange differences on translating foreign operations | B7: -20444 | C7: 12248 | D7: -6323
A8: Related tax impact | B8: -33674 | C8: 23610 | D8: 6403
A9: Total items that may be reclassified to income statement | B9: 66196 | C9: -50952 | D9: -26204
A10: Total other comprehensive income/(loss), net of tax | B10: 66301 | C10: -51475 | D10: -26035
A11: Total comprehensive income | B11: 1665817 | C11: 1474438 | D11: 1231422
A12: Total comprehensive income attributable to: Owners of the parent | B12: 1663681 | C12: 1470092 | D12: 1226428
A13: Total comprehensive income attributable to: Non-controlling interests | B13: 2136 | C13: 4346 | D13: 4994

Sheet Balance Sheet
B1: 2025 (€000) | C1: 2024 (€000) | D1: 2023 (€000) | E1: 2022 (€000) | F1: 2021 (€000) | G1: 2020 (€000) | H1: 2019 (€000) | I1: 2018 (€000) | J1: 2017 (€000) | K1: 2016 (€000)
A2: Goodwill | B2: 785182 | C2: 785182
A3: Intangible assets | B3: 1638457 | C3: 1545664 | D3: 1419699 | E3: 1307388 | F3: 1138173 | G3: 979290 | H3: 837938 | I3: 645797 | J3: 440456 | K3: 354394
A4: Property, plant and equipment | B4: 2057891 | C4: 1828784 | D4: 1575200 | E4: 1457825 | F4: 1353165 | G4: 1226630 | H4: 1069652 | I4: 850550 | J4: 710260 | K4: 669283
A5: Investments and other financial assets | B5: 96444 | C5: 80822
A6: Deferred tax assets | B6: 226005 | C6: 236791
A7: Total non-current assets | B7: 4803979 | C7: 4477243
A8: Inventories | B8: 1113904 | C8: 1088194 | D8: 948514 | E8: 674662 | F8: 540575 | G8: 460617 | H8: 420051 | I8: 391064 | J8: 393765 | K8: 323998
A9: Trade receivables | B9: 360339 | C9: 349176 | D9: 261380 | E9: 232414 | F9: 185000 | G9: 184260 | H9: 231439 | I9: 211399 | J9: 239410 | K9: 243977
A10: Receivables from financing activities | B10: 1613396 | C10: 1661632
A11: Tax receivables | B11: 31715 | C11: 15918 | D11: 11616 | E11: 16054 | F11: 14306 | G11: 12438 | H11: 21078 | I11: 128234 | J11: 30037 | K11: 43636
A12: Other current assets | B12: 159223 | C12: 137763 | D12: 130228 | E12: 153183 | F12: 122224 | G12: 76471 | H12: 92830 | I12: 64295 | J12: 45441 | K12: 53729
A13: Current financial assets | B13: 78085 | C13: 25006
A14: Cash and cash equivalents | B14: 1467711 | C14: 1742214
A15: Total operating assets | B15: =B8+B9+B12+B11+B3+B4 -> 5361529 | C15: =C8+C9+C12+C11+C3+C4 -> 4965499 | D15: =D8+D9+D12+D11+D3+D4 -> 4346637 | E15: =E8+E9+E12+E11+E3+E4 -> 3841526 | F15: =F8+F9+F12+F11+F3+F4 -> 3353443 | G15: =G8+G9+G12+G11+G3+G4 -> 2939706 | H15: =H8+H9+H12+H11+H3+H4 -> 2672988 | I15: =I8+I9+I12+I11+I3+I4 -> 2291339 | ... K15: =K8+K9+K12+K11+K3+K4 -> 1689017
A16: Total current assets | B16: 4824373 | C16: 5019903
A17: Total operating current assets | B17: =SUM(B8,B9,B11,B12) -> 1665181 | C17: =SUM(C8,C9,C11,C12) -> 1591051 | D17: =SUM(D8,D9,D11,D12) -> 1351738 | E17: =SUM(E8,E9,E11,E12) -> 1076313 | F17: =SUM(F8,F9,F11,F12) -> 862105 | G17: =SUM(G8,G9,G11,G12) -> 733786 | H17: =SUM(H8,H9,H11,H12) -> 765398 | I17: =SUM(I8,I9,I11,I12) -> 794992 | ... K17: =SUM(K8,K9,K11,K12) -> 665340
A18: Total assets | B18: 9628352 | C18: 9497146
A19: Equity attributable to owners of the parent | B19: 3906893 | C19: 3533946
A20: Non-controlling interests | B20: 7849 | C20: 9292
A21: Total equity | B21: 3914742 | C21: 3543238
A22: Employee benefits | B22: 145294 | C22: 134147
A23: Provisions | B23: 184481 | C23: 206212
A24: Deferred tax liabilities | B24: 254387 | C24: 110016
A25: Debt | B25: 2884220 | C25: 3351888
A26: Other liabilities | B26: 1391616 | C26: 1106221 | D26: 1022967 | E26: 952025 | F26: 726775 | G26: 687462 | H26: 800015 | I26: 589743 | J26: 620350 | K26: 656275
A27: Other financial liabilities | B27: 7405 | C27: 61894
A28: Trade payables | B28: 841256 | C28: 945657 | D28: 930560 | E28: 902968 | F28: 797832 | G28: 713807 | H28: 711539 | I28: 653751 | J28: 457000 | K28: 123000
A29: Tax payables | B29: 4951 | C29: 37873 | D29: 89271 | E29: 58563 | F29: 112910 | G29: 15895 | H29: 7106 | I29: 7635 | J29: 19078 | K29: 31859
A30: Total operating liabilities | B30: =B28+B29+B26 -> 2237823 | C30: =C28+C29+C26 -> 2089751 | D30: =D28+D29+D26 -> 2042798 | E30: =E28+E29+E26 -> 1913556 | F30: =F28+F29+F26 -> 1637517 | G30: =G28+G29+G26 -> 1417164 | H30: =H28+H29+H26 -> 1518660 | I30: =I28+I29+I26 -> 1251129 | ... K30: =K28+K29+K26 -> 811134
A31: Total equity and liabilities | B31: 9628352 | C31: 9497146
A32: OWC | B32: =B15-B30 -> 3123706 | C32: =C15-C30 -> 2875748 | D32: =D15-D30 -> 2303839 | E32: =E15-E30 -> 1927970 | F32: =F15-F30 -> 1715926 | G32: =G15-G30 -> 1522542 | H32: =H15-H30 -> 1154328 | I32: =I15-I30 -> 1040210 | ... K32: =K15-K30 -> 877883
A33: Number of shares outstanding | B33: 177279
A34: Stock price (as of 2/23/2026) | B34: 358.42
A35: Stock price (as of 2/23/2026, FX converted) | B35: =B34*0.85 -> 304.657
A36: Market value of equity | B36: =B33*B35 -> 54009288

Sheet Cash Flow Statement
B1: 2025 (€000) | C1: 2024 (€000) | D1: 2023 (€000) | E1: 2022 (€000) | F1: 2021 (€000) | G1: 2020 (€000) | H1: 2019 (€000) | I1: 2018 (€000) | J1: 2017 (€000) | K1: 2016 (€000) | L1: 2015 (€000)
A2: Cash and cash equivalents at beginning of year | B2: 1742214 | C2: 1121981 | D2: 1388901
A3: Net profit | B3: 1599516 | C3: 1525913 | D3: 1257457
A4: Income tax expense | B4: 464119 | C4: 363043 | D4: 344897
A5: Amortization and depreciation | B5: 661937 | C5: 666777 | D5: 662305
A6: Provision accruals | B6: 54466 | C6: 81546 | D6: 64834
A7: Result from investments | B7: -12572 | C7: -8245 | D7: -6137
A8: Financial income | B8: -168145 | C8: -147100 | D8: -132319
A9: Financial expenses | B9: 214226 | C9: 145895 | D9: 147334
A10: Other non-cash expenses, net | B10: 98169 | C10: 91909 | D10: 79813
A11: Change in inventories | B11: -76684 | C11: -157526 | D11: -309564 | E11: -153890 | F11: -81309 | G11: -67797 | H11: -40627 | I11: -4638 | J11: -88483 | K11: -33187 | L11: -2885
A12: Change in trade receivables | B12: -20617 | C12: -94029 | D12: -33381 | E12: -48400 | F12: 1771 | G12: 44477 | H12: -22377 | I12: 26890 | J12: -1745 | K12: -88847 | L12: 15693
A13: Change in trade payables | B13: -59130 | C13: 7672 | D13: 43277 | E13: 103981 | F13: 72568 | G13: 8594 | H13: 53940 | I13: 40317 | J13: 29333 | K13: 106163 | L13: -45792
A14: Change in receivables from financing activities | B14: -154580 | C14: -118687 | D14: -107247
A15: Change in other operating assets and liabilities | B15: 222377 | C15: -20045 | D15: 48642 | E15: 140008 | F15: -29840 | G15: -137313 | H15: 145547 | I15: -83013 | J15: -72803 | K15: 7149 | L15: -24698
A16: Finance income received | B16: 38035 | C16: 49673 | D16: 32432
A17: Finance costs paid | B17: -126257 | C17: -50354 | D17: -83243
A18: Income tax paid | B18: -385554 | C18: -409786 | D18: -292463
A19: Total cash flows from operating activities | B19: 2349306 | C19: 1926656 | D19: 1716637
A20: Investments in intangible assets | B20: -457976 | C20: -506874 | D20: -487148
A21: Investments in property, plant and equipment | B21: -485210 | C21: -482277 | D21: -381762
A22: Acquisition of subsidiary and other investments | B22: -1352 | C22: 0 | D22: 0
A23: Proceeds from sale of PPE and intangibles | B23: 400 | C23: 2041 | D23: 2458
A24: Total cash flows used in investing activities | B24: -944138 | C24: -987110 | D24: -866452
A25: Repayments of bonds and notes | B25: -450963 | C25: 0 | D25: -575702
A26: Proceeds from bonds and notes | B26: 0 | C26: 496145 | D26: 0
A27: Repayments of securitizations | B27: -33294 | C27: -243649 | D27: -49611
... A40: Cash and cash equivalents at end of year | B40: 1467711 | C40: 1742214 | D40: 1121981

Sheet Changes in Equity
B1: 2025 (€000) | C1: 2024 (€000) | D1: 2023 (€000)
A2: Share capital | B2: 2573 | C2: 2573 | D2: 2573
A3: Retained earnings and other reserves | B3: 3824443 | C3: 3518258 | D3: 2993422
A4: Cash flow hedge reserve | B4: 49792 | C4: -36848 | D4: 26352
A5: Currency translation differences | B5: 38665 | C5: 58648 | D5: 46710
A6: Remeasurement of defined benefit plans | B6: -8580 | C6: -8685 | D6: -8169
A7: Equity attributable to owners of the parent | B7: 3906893 | C7: 3533946 | D7: 3060888
A8: Non-controlling interests | B8: 7849 | C8: 9292 | D8: 9734
A9: Total equity | B9: 3914742 | C9: 3543238 | D9: 3070622

Sheet DCF (Structural Stability)
A1: Historical FCFF | F1: Forecasted FCFF | Q1: WACC
B2: 2023 | C2: 2024 | D2: 2025 | F2: 2026 | G2: 2027 | H2: 2028 | I2: 2029 | J2: 2030 | K2: 2031 | L2: 2032 | M2: 2033 | N2: 2034 | O2: 2035 | Q2: Market Value of Equity | R2: ='Balance Sheet'!B36 -> 54009288
A3: Revenue | B3: ='Income Statement'!D2 -> 5970146 | C3: ='Income Statement'!C2 -> 6676668 | D3: ='Income Statement'!B2 -> 7145768 | F3: =D3*(1+F4) -> 7819621.4 | G3: =F3*(1+G4) -> 8501152.1 | H3: =G3*(1+H4) -> 9181345.7 | I3: =H3*(1+I4) -> 9850366.2 | J3: =I3*(1+J4) -> 10497760 | K3: =J3*(1+K4) -> 11112700 | L3: =K3*(1+L4) -> 11684267 | M3: =L3*(1+M4) -> 12201753 | N3: =M3*(1+N4) -> 12654982 | O3: =N3*(1+O4) -> 13034631 | Q3: Total Debt | R3: ='Balance Sheet'!B25 -> 2884220
A4: Revenue Growth | C4: =(C3-B3)/B3 -> 0.1183425 | D4: =(D3-C3)/C3 -> 0.070259597 | F4: =$D$6 -> 0.094301048 | G4: =F4-($F$4-$O$4)/9 -> 0.087156487 | H4: =G4-($F$4-$O$4)/9 -> 0.080011926 | I4: =H4-($F$4-$O$4)/9 -> 0.072867365 | J4: =I4-($F$4-$O$4)/9 -> 0.065722804 | K4: =J4-($F$4-$O$4)/9 -> 0.058578244 | L4: =K4-($F$4-$O$4)/9 -> 0.051433683 | M4: =L4-($F$4-$O$4)/9 -> 0.044289122 | N4: =M4-($F$4-$O$4)/9 -> 0.037144561 | O4: 0.03 | Q4: W(E) | R4: =R2/(R2+R3) -> 0.94930494
A5: Pre-Tax Income | B5: ='Income Statement'!D12 -> 1602354 | C5: ='Income Statement'!C12 -> 1888956 | D5: ='Income Statement'!B12 -> 2063635 | Q5: W(D) | R5: =R3/(R3+R2) -> 0.050695063
A6: Average Growth Rate | D6: =AVERAGE(C4:D4) -> 0.094301048 | Q6: Beta | R6: 0.52
A7: EBIT | B7: ='Income Statement'!D8 -> 1617369 | C7: ='Income Statement'!C8 -> 1887751 | D7: ='Income Statement'!B8 -> 2109716 | F7: =F8*F3 -> 2212660.6 | G7: =G8*G3 -> 2405508.3 | H7: =H8*H3 -> 2597977.6 | I7: =I8*I3 -> 2787285.4 | J7: =J8*J3 -> 2970473.7 | K7: =K8*K3 -> 3144478.8 | L7: =L8*L3 -> 3306210.9 | M7: =M8*M3 -> 3452640.1 | ... O7: =O8*O3 -> 3688313.5 | Q7: MRP | R7: 0.055
A8: EBIT Margin | B8: =B7/B3 -> 0.27090946 | C8: =C7/C3 -> 0.28273849 | D8: =D7/D3 -> 0.29523992 | F8: =$D$9 -> 0.28296262 | G8: =$D$9 -> 0.28296262 | H8: =$D$9 -> 0.28296262 | I8: =$D$9 -> 0.28296262 | J8: =$D$9 -> 0.28296262 | K8: =$D$9 -> 0.28296262 | L8: =$D$9 -> 0.28296262 | M8: =$D$9 -> 0.28296262 | ... O8: =$D$9 -> 0.28296262 | Q8: Risk Free Rate | R8: 0.0279
A9: Average EBIT Margin | D9: =AVERAGE(B8:D8) -> 0.28296262 | Q9: Cost of Equity | R9: =R8+R6*R7 -> 0.0565
A10: Tax Expense | B10: ='Income Statement'!D14 -> 344897 | C10: ='Income Statement'!C14 -> 363043 | D10: ='Income Statement'!B14 -> 464119 | F10: =F11*F7 -> 466384.58 | G10: =G11*G7 -> 507033.03 | H10: =H11*H7 -> 547601.71 | I10: =I11*I7 -> 587504.01 | J10: =J11*J7 -> 626116.42 | K10: =K11*K7 -> 662793.22 | L10: =L11*L7 -> 696883.12 | M10: =M11*M7 -> 727747.46 | ... O10: =O11*O7 -> 777422.7 | Q10: Interest Expense | R10: ='Income Statement'!B13 -> 41168
A11: Tax Rate | B11: =B10/B5 -> 0.21524395 | C11: =C10/C5 -> 0.19219241 | D11: =D10/D5 -> 0.22490363 | F11: =$D$12 -> 0.21077999 | G11: =$D$12 -> 0.21077999 | H11: =$D$12 -> 0.21077999 | I11: =$D$12 -> 0.21077999 | J11: =$D$12 -> 0.21077999 | K11: =$D$12 -> 0.21077999 | L11: =$D$12 -> 0.21077999 | M11: =$D$12 -> 0.21077999 | ... O11: =$D$12 -> 0.21077999 | Q11: Cost of Debt | R11: =R10/R3 -> 0.01427353
A12: Average Tax Rate | D12: =AVERAGE(B11:D11) -> 0.21077999 | Q12: Tax Rate | R12: =D12 -> 0.21077999
A13: NOPAT | B13: =B7*(1-B11) -> 1269240.1 | C13: =C7*(1-C11) -> 1524939.6 | D13: =D7*(1-D11) -> 1635233.2 | F13: =F7*(1-F11) -> 1746276 | G13: =G7*(1-G11) -> 1898475.3 | H13: =H7*(1-H11) -> 2050375.9 | I13: =I7*(1-I11) -> 2199781.4 | J13: =J7*(1-J11) -> 2344357.2 | K13: =K7*(1-K11) -> 2481685.6 | L13: =L7*(1-L11) -> 2609327.8 | M13: =M7*(1-M11) -> 2724892.6 | ... O13: =O7*(1-O11) -> 2910890.8 | Q13: After-Tax Cost of Debt | R13: =R11*(1-R12) -> 0.011264955
A14: Invested Capital | C14: =('Balance Sheet'!C15-'Balance Sheet'!C30)+'Balance Sheet'!C4+'Balance Sheet'!C3 -> 6250196 | D14: =('Balance Sheet'!B15-'Balance Sheet'!B30)+'Balance Sheet'!B4+'Balance Sheet'!B3 -> 6820054 | Q14: Terminal Growth Rate | R14: 0.03
A15: ROIC | D15: =D13/C14 -> 0.26162911 | F15: =F13/D14 -> 0.25605017 | G15: =$D$16 -> 0.25883964 | H15: =G15-($G$15-$O$15)/8 -> 0.26648469 | I15: =H15-($G$15-$O$15)/8 -> 0.27412973 | J15: =I15-($G$15-$O$15)/8 -> 0.28177478 | K15: =J15-($G$15-$O$15)/8 -> 0.28941982 | L15: =K15-($G$15-$O$15)/8 -> 0.29706487 | M15: =L15-($G$15-$O$15)/8 -> 0.30470991 | N15: =M15-($G$15-$O$15)/8 -> 0.31235496 | O15: 0.32 | Q15: WACC | R15: =R4*R9+R5*R13 -> 0.054206807
A16: Average ROIC | D16: =AVERAGE(D15,F15) -> 0.25883964
A17: Reinvestment | B17: =B21-B18+B24 -> -1782241 | C17: =C21-C18+C24 -> -1919856 | D17: =D21-D18+D24 -> -1539177 | F17: =F4/F15*F13 -> 643138.24 | G17: =G4/G15*G13 -> 639254.62 | H17: =H4/H15*H13 -> 615624.6 | I17: =I4/I15*I13 -> 584731.46 | J17: =J4/J15*J13 -> 546811.66 | K17: =K4/K15*K13 -> 502290.34 | L17: =L4/L15*L13 -> 451777.89 | M17: =M4/M15*M13 -> 396059 | ... O17: =O4/O15*O13 -> 272896.01
A18: D&A | B18: ='Cash Flow Statement'!D5 -> 662305 | C18: ='Cash Flow Statement'!C5 -> 666777 | D18: ='Cash Flow Statement'!B5 -> 661937 | F18: =F19*F3 -> 790919.02 | G18: =G19*G3 -> 859852.74 | H18: =H19*H3 -> 928651.21 | I18: =I19*I3 -> 996319.58 | J18: =J19*J3 -> 1061800.5 | K18: =K19*K3 -> 1123998.9 | L18: =L19*L3 -> 1181810.3 | M18: =M19*M3 -> 1234151.7 | ... O18: =O19*O3 -> 1318393.5
A19: D&A (% of Revenue) | B19: =B18/B3 -> 0.11093615 | C19: =C18/C3 -> 0.09986673 | D19: =D18/D3 -> 0.09263343 | F19: =$D$20 -> 0.10114544 | G19: =$D$20 -> 0.10114544 | H19: =$D$20 -> 0.10114544 | I19: =$D$20 -> 0.10114544 | J19: =$D$20 -> 0.10114544 | K19: =$D$20 -> 0.10114544 | L19: =$D$20 -> 0.10114544 | M19: =$D$20 -> 0.10114544 | ... O19: =$D$20 -> 0.10114544
A20: Average D&A | D20: =AVERAGE(B19:D19) -> 0.10114544
A21: CapEx | B21: =SUM('Cash Flow Statement'!D20:D21) -> -868910 | C21: =SUM('Cash Flow Statement'!C20:C21) -> -989151 | D21: =SUM('Cash Flow Statement'!B20:B21) -> -943186 | F21: =F17+F18-F24 -> 1622635.5 | G21: =G17+G18-G24 -> 1704121.4 | H21: =H17+H18-H24 -> 1765693.4 | I21: =I17+I18-I24 -> 1818602.8 | J21: =J17+J18-J24 -> 1861776.5 | K21: =K17+K18-K24 -> 1894283.5 | L21: =L17+L18-L24 -> 1915366.4 | M21: =M17+M18-M24 -> 1924468.5 | ... O21: =O17+O18-O24 -> 1905633.1
A22: CapEx (% of Revenue) | B22: =B21/B3 -> -0.1455425 | C22: =C21/C3 -> -0.14815039 | D22: =D21/D3 -> -0.13199225
A23: Average CapEx | D23: =AVERAGE(B22:D22) -> -0.14189505
A24: Change in NWC | B24: ='Cash Flow Statement'!D11+'Cash Flow Statement'!D12+'Cash Flow Statement'!D13+'Cash Flow Statement'!D15 -> -251026 | C24: ='Cash Flow Statement'!C11+'Cash Flow Statement'!C12+'Cash Flow Statement'!C13+'Cash Flow Statement'!C15 -> -263928 | D24: ='Cash Flow Statement'!B11+'Cash Flow Statement'!B12+'Cash Flow Statement'!B13+'Cash Flow Statement'!B15 -> 65946 | F24: =F25*F3 -> -188578.24 | G24: =G25*G3 -> -205014.06 | H24: =H25*H3 -> -221417.63 | I24: =I25*I3 -> -237551.75 | J24: =J25*J3 -> -253164.31 | K24: =K25*K3 -> -267994.23 | L24: =L25*L3 -> -281778.16 | M24: =M25*M3 -> -294257.87 | ... O24: =O25*O3 -> -314343.59
A25: Change in NWC (% of Revenue) | B25: =B24/B3 -> -0.042046878 | C25: =C24/C3 -> -0.039529897 | D25: =D24/D3 -> 0.0092286791 | F25: =$D$26 -> -0.024116032 | G25: =$D$26 -> -0.024116032 | H25: =$D$26 -> -0.024116032 | I25: =$D$26 -> -0.024116032 | J25: =$D$26 -> -0.024116032 | K25: =$D$26 -> -0.024116032 | L25: =$D$26 -> -0.024116032 | M25: =$D$26 -> -0.024116032 | ... O25: =$D$26 -> -0.024116032
A26: Average Change in NWC | D26: =AVERAGE(B25:D25) -> -0.024116032
A27: FCFF | B27: =B13+B18-B21-B24 -> 3051481.1 | C27: =C13+C18-C21-C24 -> 3444795.6 | D27: =D13+D18-D21-D24 -> 3174410.2 | F27: =F13+F18-F21-F24 -> 1103137.8 | G27: =G13+G18-G21-G24 -> 1259220.7 | H27: =H13+H18-H21-H24 -> 1434751.3 | I27: =I13+I18-I21-I24 -> 1615050 | J27: =J13+J18-J21-J24 -> 1797545.6 | K27: =K13+K18-K21-K24 -> 1979395.2 | L27: =L13+L18-L21-L24 -> 2157549.9 | M27: =M13+M18-M21-M24 -> 2328833.6 | ... O27: =O13+O18-O21-O24 -> 2637994.8
A28: PV(FCFF) | F28: =F27/(1+$R$15)^1 -> 1046414.9 | G28: =G27/(1+$R$15)^2 -> 1133053 | H28: =H27/(1+$R$15)^3 -> 1224613.9 | I28: =I27/(1+$R$15)^4 -> 1307623.4 | J28: =J27/(1+$R$15)^5 -> 1380545.8 | K28: =K27/(1+$R$15)^6 -> 1442041 | L28: =L27/(1+$R$15)^7 -> 1491008.6 | M28: =M27/(1+$R$15)^8 -> 1526623.5 | N28: =N27/(1+$R$15)^9 -> 1548363 | O28: =O27/(1+$R$15)^10 -> 1556022.1
A29: Terminal Value | O29: =(O27*(1+R14))/(R15-R14) -> 1.1224672e+08
A30: PV(TV) | O30: =O29/(1+R15)^10 -> 66208767
A31: Enterprise Value | O31: =SUM(F28:O28,O30) -> 79865076
A32: Equity Value | O32: =O31-R3+'Cash Flow Statement'!B40 -> 78448567
A33: Intrinsic Price | O33: =O32/'Balance Sheet'!B33 -> 442.51472

Sheet DCF (EV) NEW
N1: Transition Stage (BEV) | S1: Stabilization Stage
A2: Historical FCFF | N2: Forecasted FCFF | Y2: WACC
B3: 2015 | C3: 2016 | D3: 2017 | E3: 2018 | F3: 2019 | G3: 2020 | H3: 2021 | I3: 2022 | J3: 2023 | K3: 2024 | L3: 2025 | N3: 2026 | O3: 2027 | P3: 2028 | Q3: 2029 | R3: 2030 | S3: 2031 | T3: 2032 | U3: 2033 | V3: 2034 | W3: 2035 | Y3: Market Value of Equity | Z3: ='Balance Sheet'!B36 -> 54009288
A4: Revenue | B4: =B10+B12 -> 2854000 | C4: =C10+C12 -> 3105000 | D4: =D10+D12 -> 3417000 | E4: =E10+E12 -> 3420321 | F4: =F10+F12 -> 3766615 | G4: =G10+G12 -> 3459790 | H4: =H10+H12 -> 4270894 | I4: =I10+I12 -> 5095254 | ... L4: =L10+L12 -> 7145768 | N4: =N10+N12 -> 8101205.4 | O4: =O10+O12 -> 9184424 | P4: =P10+P12 -> 10226228 | Q4: =Q10+Q12 -> 11386613 | R4: =R10+R12 -> 12679127 | S4: =S10+S12 -> 13947661 | T4: =T10+T12 -> 15099884 | U4: =U10+U12 -> 16082987 | ... W4: =W10+W12 -> 17353347 | Y4: Total Debt | Z4: ='Balance Sheet'!B25 -> 2884220 | AD4: EBIT Margin | AE4: Intrinsic Value | AG4: Beta / Terminal Growth | AH4: 0.025 | AI4: 0.03 | AJ4: 0.035
A5: Revenue Growth | C5: =(C4-B4)/B4 -> 0.087946741 | D5: =(D4-C4)/C4 -> 0.10048309 | E5: =(E4-D4)/D4 -> 0.00097190518 | F5: =(F4-E4)/E4 -> 0.10124605 | G5: =(G4-F4)/F4 -> -0.081459082 | H5: =(H4-G4)/G4 -> 0.23443735 | I5: =(I4-H4)/H4 -> 0.19301814 | J5: =(J4-I4)/I4 -> 0.17170724 | ... L5: =(L4-K4)/K4 -> 0.070259597 | N5: =(N4-L4)/L4 -> 0.13370675 | O5: =(O4-N4)/N4 -> 0.13371079 | P5: =(P4-O4)/O4 -> 0.11343163 | Q5: =(Q4-P4)/P4 -> 0.11347145 | R5: =(R4-Q4)/Q4 -> 0.11351173 | S5: =(S4-R4)/R4 -> 0.10004895 | T5: =(T4-S4)/S4 -> 0.082610492 | U5: =(U4-T4)/T4 -> 0.065106693 | V5: =(V4-U4)/U4 -> 0.047560948 | W5: =(W4-V4)/V4 -> 0.03 | Y5: W(E) | Z5: =Z3/(Z3+Z4) -> 0.94930494 | AD5: 0.22 | AE5: 198.64903 | AG5: 0.7 | AH5: 336.77868 | AI5: 377.6376 | AJ5: 432.80664
A6: Total Shipments | B6: 7664 | C6: 8014 | D6: 8398 | E6: 9251 | F6: 10131 | G6: 9119 | H6: 11155 | I6: 13221 | J6: 13663 | K6: 13752 | L6: 13640 | N6: =L6*(1+N7) -> 13708.2 | O6: =N6*(1+O7) -> 13776.741 | P6: =O6*(1+P7) -> 13845.625 | Q6: =P6*(1+Q7) -> 13914.853 | R6: =Q6*(1+R7) -> 13984.427 | S6: =R6*(1+S7) -> 14040.365 | T6: =S6*(1+T7) -> 14082.486 | U6: =T6*(1+U7) -> 14110.651 | V6: =U6*(1+V7) -> 14124.762 | W6: =V6*(1+W7) -> 14124.762 | Y6: W(D) | Z6: =Z4/(Z4+Z3) -> 0.050695063 | AD6: 0.24 | AE6: 212.74399 | AG6: 0.8 | AH6: 292.03711 | AI6: 321.83412 | AJ6: 360.45371
A7: Total Shipment Growth | B7: =(B6-7255)/7255 -> 0.056374914 | C7: =(C6-B6)/B6 -> 0.045668058 | D7: =(D6-C6)/C6 -> 0.047916147 | E7: =(E6-D6)/D6 -> 0.1015718 | F7: =(F6-E6)/E6 -> 0.095124851 | G7: =(G6-F6)/F6 -> -0.099891422 | H7: =(H6-G6)/G6 -> 0.2232701 | I7: =(I6-H6)/H6 -> 0.18520843 | J7: =(J6-I6)/I6 -> 0.033431662 | ... L7: =(L6-K6)/K6 -> -0.0081442699 | N7: 0.005 | O7: 0.005 | P7: 0.005 | Q7: 0.005 | R7: 0.005 | S7: 0.004 | T7: 0.003 | U7: 0.002 | V7: 0.001 | W7: 0 | Y7: Beta | Z7: 1.07 | AD7: 0.26 | AE7: 226.83896 | AG7: 0.9 | AH7: 256.97579 | AI7: 279.43127 | AJ7: 307.64533
A8: Hybrid Shipments / Hybrid & BEV (in the projections) | H8: =H6*H9 -> 1673.25 | I8: =I6*I9 -> 2908.62 | J8: =J6*J9 -> 6011.72 | K8: =K6*K9 -> 7054.776 | L8: =L6*L9 -> 5728.8 | N8: =N6*N9 -> 6168.69 | O8: =O6*O9 -> 6888.3705 | P8: =P6*P9 -> 6922.8124 | Q8: =Q6*Q9 -> 7653.1691 | R8: =R6*R9 -> 8390.6563 | S8: =S6*S9 -> 8424.2189 | T8: =T6*T9 -> 8449.4915 | U8: =U6*U9 -> 8466.3905 | ... W8: =W6*W9 -> 8474.8569 | Y8: MRP | Z8: 0.055 | AD8: 0.28 | AE8: 240.93393 | AG8: 1.07 | AH8: 212.14875 | AI8: 226.83896 | AJ8: 244.59789
A9: Hybrid Shipments / Hybrid & BEV (% of Total Shipments) | H9: 0.15 | I9: 0.22 | J9: 0.44 | K9: 0.513 | L9: 0.42 | N9: 0.45 | O9: 0.5 | P9: 0.5 | Q9: 0.55 | R9: 0.6 | S9: 0.6 | T9: 0.6 | U9: 0.6 | V9: 0.6 | W9: 0.6 | Y9: Risk Free Rate | Z9: 0.02786 | AD9: 0.3 | AE9: 255.02889 | AG9: 1.1 | AH9: 205.65852 | AI9: 219.3705 | AJ9: 235.85611
A10: Sponsorship, Commercial, Brand, and Other Revenue | B10: =441000+219000+114000 -> 774000 | C10: =488000+338000+99000 -> 925000 | D10: =494000+373000+94000 -> 961000 | E10: =505701+284546+94829 -> 885076 | F10: =538238+198308+104348 -> 840894 | G10: =390002+150655+83963 -> 624620 | H10: =450860+189432+77764 -> 718056 | I10: =498861+155342+119931 -> 774134 | J10: =571759+279206 -> 850965 | K10: =669776+279204 -> 948980 | L10: =819551+320974 -> 1140525 | N10: =L10*(1+N11) -> 1287414.9 | O10: =N10*(1+O11) -> 1453222.9 | P10: =O10*(1+P11) -> 1640385.6 | Q10: =P10*(1+Q11) -> 1851653.2 | R10: =Q10*(1+R11) -> 2090130.3 | S10: =R10*(1+S11) -> 2359321.2 | T10: =S10*(1+T11) -> 2604911.4 | U10: =T10*(1+U11) -> 2811730.2 | V10: =U10*(1+V11) -> 2965525.8 | W10: =V10*(1+W11) -> 3054491.6 | Y10: Cost of Equity | Z10: =Z9+Z7*Z8 -> 0.08671
A11: Sponsorship, Commercial, Brand, and Other Revenue Growth | C11: =(C10-B10)/B10 -> 0.19509044 | D11: =(D10-C10)/C10 -> 0.038918919 | E11: =(E10-D10)/D10 -> -0.079005203 | F11: =(F10-E10)/E10 -> -0.049918877 | G11: =(G10-F10)/F10 -> -0.25719532 | H11: =(H10-G10)/G10 -> 0.14958855 | I11: =(I10-H10)/H10 -> 0.078096973 | J11: =(J10-I10)/I10 -> 0.099247675 | ... L11: =(L10-K10)/K10 -> 0.20184303 | N11: =AVERAGE($H$11:$L$11) -> 0.12879145 | O11: =AVERAGE($H$11:$L$11) -> 0.12879145 | P11: =AVERAGE($H$11:$L$11) -> 0.12879145 | Q11: =AVERAGE($H$11:$L$11) -> 0.12879145 | R11: =AVERAGE($H$11:$L$11) -> 0.12879145 | S11: =AVERAGE($H$11:$L$11) -> 0.12879145 | T11: =S11-(($S$11-$W$11)/4) -> 0.10409358 | U11: =T11-(($S$11-$W$11)/4) -> 0.079395723 | V11: =U11-(($S$11-$W$11)/4) -> 0.054697862 | W11: 0.03 | Y11: Interest Expense | Z11: ='Income Statement'!B13 -> 41168
A12: Automotive Revenue | B12: 2080000 | C12: 2180000 | D12: 2456000 | E12: 2535245 | F12: 2925721 | G12: 2835170 | H12: 3552838 | I12: 4321120 | J12: 5119181 | K12: 5727688 | L12: 6005243 | N12: =N6*N13 -> 6813790.5 | O12: =O6*O13 -> 7731201.1 | P12: =P6*P13 -> 8585842.6 | Q12: =Q6*Q13 -> 9534959.9 | R12: =R6*R13 -> 10588997 | S12: =S6*S13 -> 11588339 | T12: =T6*T13 -> 12494972 | U12: =U6*U13 -> 13271257 | ... W12: =W6*W13 -> 14298855 | Y12: Cost of Debt | Z12: =Z11/Z4 -> 0.01427353 | AG12: WACC / Terminal Growth | AH12: 0.025 | AI12: 0.03 | AJ12: 0.035
A13: Average Selling Price (ASP) | B13: =B12/B6 -> 271.39875 | C13: =C12/C6 -> 272.02396 | D13: =D12/D6 -> 292.45058 | E13: =E12/E6 -> 274.05091 | F13: =F12/F6 -> 288.78896 | G13: =G12/G6 -> 310.90799 | H13: =H12/H6 -> 318.49736 | I13: =I12/I6 -> 326.83761 | ... L13: =L12/L6 -> 440.26708 | N13: =L13*(1+N14) -> 497.05946 | O13: =N13*(1+O14) -> 561.17779 | P13: =O13*(1+P14) -> 620.11233 | Q13: =P13*(1+Q14) -> 685.23613 | R13: =Q13*(1+R14) -> 757.1992 | S13: =R13*(1+S14) -> 825.35885 | T13: =S13*(1+T14) -> 887.27036 | U13: =T13*(1+U14) -> 940.51345 | V13: =U13*(1+V14) -> 982.8402 | W13: =V13*(1+W14) -> 1012.3254 | Y13: Tax Rate | Z13: =W21 -> 0.23081525 | AG13: 0.07 | AH13: 283.05699 | AI13: 310.86481 | AJ13: 346.61772
A14: ASP Growth | C14: =(C13-B13)/B13 -> 0.0023036609 | D14: =(D13-C13)/C13 -> 0.075091273 | E14: =(E13-D13)/D13 -> -0.062915484 | F14: =(F13-E13)/E13 -> 0.053778515 | G14: =(G13-F13)/F13 -> 0.076592365 | H14: =(H13-G13)/G13 -> 0.024410312 | I14: =(I13-H13)/H13 -> 0.02618625 | J14: =(J13-I13)/I13 -> 0.14636362 | ... L14: =(L13-K13)/K13 -> 0.057067514 | N14: =AVERAGE($J$14:$K$14) -> 0.12899529 | O14: =AVERAGE($J$14:$K$14) -> 0.12899529 | P14: =AVERAGE($J$14:$L$14) -> 0.10501937 | Q14: =AVERAGE($J$14:$L$14) -> 0.10501937 | R14: =AVERAGE($J$14:$L$14) -> 0.10501937 | S14: =R14-(($R$14-$W$14)/5) -> 0.090015492 | T14: =S14-(($R$14-$W$14)/5) -> 0.075011619 | U14: =T14-(($R$14-$W$14)/5) -> 0.060007746 | V14: =U14-(($R$14-$W$14)/5) -> 0.045003873 | W14: 0.03 | Y14: After-Tax Cost of Debt | Z14: =Z12*(1-Z13) -> 0.010978981 | AG14: 0.08 | AH14: 225.0288 | AI14: 241.76847 | AJ14: 262.22807
A15: Research & Development (R&D) | B15: 562000 | C15: 614000 | D15: 657000 | E15: 643038 | F15: 699211 | G15: 707385 | H15: 768104 | I15: 775572 | J15: 538903 | K15: 563311 | L15: 592690 | N15: =N4*N16 -> 1488505.5 | O15: =O4*O16 -> 1687534.7 | P15: =P4*P16 -> 1878954.5 | Q15: =Q4*Q16 -> 2092162.2 | R15: =R4*R16 -> 2329647.2 | S15: =S4*S16 -> 2289689.2 | T15: =T4*T16 -> 2183249.1 | U15: =U4*U16 -> 2010555.8 | ... W15: =W4*W16 -> 1489953.6 | Y15: Terminal Growth Rate | Z15: 0.03 | AG15: 0.082870811 | AH15: 212.14875 | AI15: 226.83896 | AJ15: 244.59789
A16: R&D (% of Revenue) | B16: =B15/B4 -> 0.19691661 | C16: =C15/C4 -> 0.19774557 | D16: =D15/D4 -> 0.19227392 | E16: =E15/E4 -> 0.18800516 | F16: =F15/F4 -> 0.18563379 | G16: =G15/G4 -> 0.20445894 | H16: =H15/H4 -> 0.17984619 | I16: =I15/I4 -> 0.15221459 | ... L16: =L15/L4 -> 0.082942799 | N16: =AVERAGE($D$16:$I$16) -> 0.18373876 | O16: =AVERAGE($D$16:$I$16) -> 0.18373876 | P16: =AVERAGE($D$16:$I$16) -> 0.18373876 | Q16: =AVERAGE($D$16:$I$16) -> 0.18373876 | R16: =AVERAGE($D$16:$I$16) -> 0.18373876 | S16: =R16-(($R$16-$W$16)/5) -> 0.16416296 | T16: =S16-(($R$16-$W$16)/5) -> 0.14458715 | U16: =T16-(($R$16-$W$16)/5) -> 0.12501134 | V16: =U16-(($R$16-$W$16)/5) -> 0.10543553 | W16: =AVERAGE($J$16:$L$16) -> 0.085859726 | Y16: WACC | Z16: =Z5*Z10+Z6*Z14 -> 0.082870811 | AG16: 0.09 | AH16: 185.20018 | AI16: 196.0642 | AJ16: 208.90349
A17: Pre-Tax Income | B17: 290000 | C17: 400000 | D17: 746000 | E17: 802944 | F17: 875364 | G17: 667035 | H17: 1042231 | I17: 1177766 | J17: ='Income Statement'!D12 -> 1602354 | K17: ='Income Statement'!C12 -> 1888956 | L17: ='Income Statement'!B12 -> 2063635
A18: EBIT | B18: 444000 | C18: 595000 | D18: 775000 | E18: 826507 | F18: 917446 | G18: 716127 | H18: 1075488 | I18: 1227382 | J18: ='Income Statement'!D8 -> 1617369 | K18: ='Income Statement'!C8 -> 1887751 | L18: ='Income Statement'!B8 -> 2109716 | N18: =N4*N19 -> 1965758.4 | O18: =O4*O19 -> 2142086.2 | P18: =P4*P19 -> 2385066.6 | Q18: =Q4*Q19 -> 2655703.5 | R18: =R4*R19 -> 2957157 | S18: =S4*S19 -> 3347438.5 | T18: =T4*T19 -> 3774970.9 | U18: =U4*U19 -> 4101161.7 | ... W18: =W4*W19 -> 4511870.1
A19: EBIT Margin | B19: =B18/B4 -> 0.15557113 | C19: =C18/C4 -> 0.19162641 | D19: =D18/D4 -> 0.22680714 | E19: =E18/E4 -> 0.24164603 | F19: =F18/F4 -> 0.24357308 | G19: =G18/G4 -> 0.20698568 | H19: =H18/H4 -> 0.251818 | I19: =I18/I4 -> 0.2408873 | ... L19: =L18/L4 -> 0.29523992 | N19: =AVERAGE($G$19:$J$19) -> 0.24265011 | O19: =AVERAGE($G$19:$I$19) -> 0.23323033 | P19: =AVERAGE($G$19:$I$19) -> 0.23323033 | Q19: =AVERAGE($G$19:$I$19) -> 0.23323033 | R19: =AVERAGE($G$19:$I$19) -> 0.23323033 | S19: 0.24 | T19: 0.25 | U19: 0.255 | V19: 0.26 | W19: 0.26
A20: Tax Expense | B20: 144000 | C20: 167000 | D20: 209000 | E20: 16317 | F20: 176656 | G20: 58155 | H20: 209095 | I20: 238472 | J20: ='Income Statement'!D14 -> 344897 | K20: ='Income Statement'!C14 -> 363043 | L20: ='Income Statement'!B14 -> 464119 | N20: =N21*N4 -> 1869881.7 | O20: =O21*O4 -> 2119905.1 | P20: =P21*P4 -> 2360369.4 | Q20: =Q21*Q4 -> 2628203.9 | R20: =R21*R4 -> 2926535.9 | S20: =S21*S4 -> 3219332.8 | T20: =T21*T4 -> 3485283.4 | U20: =U21*U4 -> 3712198.7 | ... W20: =W21*W4 -> 4005417
A21: Tax Rate | B21: =B20/B17 -> 0.49655172 | C21: =C20/C17 -> 0.4175 | D21: =D20/D17 -> 0.28016086 | E21: =E20/E17 -> 0.020321467 | F21: =F20/F17 -> 0.20180862 | G21: =G20/G17 -> 0.087184331 | H21: =H20/H17 -> 0.20062251 | I21: =I20/I17 -> 0.20247825 | ... L21: =L20/L17 -> 0.22490363 | N21: =AVERAGE($B$21:$L$21) -> 0.23081525 | O21: =AVERAGE($B$21:$L$21) -> 0.23081525 | P21: =AVERAGE($B$21:$L$21) -> 0.23081525 | Q21: =AVERAGE($B$21:$L$21) -> 0.23081525 | R21: =AVERAGE($B$21:$L$21) -> 0.23081525 | S21: =AVERAGE($B$21:$L$21) -> 0.23081525 | T21: =AVERAGE($B$21:$L$21) -> 0.23081525 | U21: =AVERAGE($B$21:$L$21) -> 0.23081525 | ... W21: =AVERAGE($B$21:$L$21) -> 0.23081525
A22: NOPAT | B22: =B18*(1-B21) -> 223531.03 | C22: =C18*(1-C21) -> 346587.5 | D22: =D18*(1-D21) -> 557875.34 | E22: =E18*(1-E21) -> 809711.17 | F22: =F18*(1-F21) -> 732297.49 | G22: =G18*(1-G21) -> 653691.95 | H22: =H18*(1-H21) -> 859720.9 | I22: =I18*(1-I21) -> 978863.84 | ... L22: =L18*(1-L21) -> 1635233.2 | N22: =N18*(1-N21) -> 1512031.4 | O22: =O18*(1-O21) -> 1647660.1 | P22: =P18*(1-P21) -> 1834556.8 | Q22: =Q18*(1-Q21) -> 2042726.7 | R22: =R18*(1-R21) -> 2274600.1 | S22: =S18*(1-S21) -> 2574798.7 | T22: =T18*(1-T21) -> 2903650.1 | U22: =U18*(1-U21) -> 3154551.1 | ... W22: =W18*(1-W21) -> 3470461.7
A23: Invested Capital | C23: ='Balance Sheet'!K32 -> 877883 | D23: ='Balance Sheet'!J32 -> 762941 | E23: ='Balance Sheet'!I32 -> 1040210 | F23: ='Balance Sheet'!H32 -> 1154328 | G23: ='Balance Sheet'!G32 -> 1522542 | H23: ='Balance Sheet'!F32 -> 1715926 | I23: ='Balance Sheet'!E32 -> 1927970 | J23: ='Balance Sheet'!D32 -> 2303839 | K23: ='Balance Sheet'!C32 -> 2875748 | L23: ='Balance Sheet'!B32 -> 3123706 | N23: =N4*N24 -> 3645542.4 | O23: =O4*O24 -> 4132990.8 | P23: =P4*P24 -> 4601802.7 | Q23: =Q4*Q24 -> 5123975.9 | R23: =R4*R24 -> 5705607.3 | S23: =S4*S24 -> 6136970.7 | T23: =T4*T24 -> 6492950 | U23: =U4*U24 -> 6754854.6 | ... W23: =W4*W24 -> 6941338.6
A24: Invested Capital (% of Revenue) | C24: =C23/C4 -> 0.28273205 | D24: =D23/D4 -> 0.22327802 | E24: =E23/E4 -> 0.30412643 | F24: =F23/F4 -> 0.30646296 | G24: =G23/G4 -> 0.44006775 | H24: =H23/H4 -> 0.40177209 | I24: =I23/I4 -> 0.37838545 | J24: =J23/J4 -> 0.38589324 | ... L24: =L23/L4 -> 0.4371407 | N24: 0.45 | O24: 0.45 | P24: 0.45 | Q24: 0.45 | R24: 0.45 | S24: 0.44 | T24: 0.43 | U24: 0.42 | V24: 0.41 | W24: 0.4
A25: ROIC | D25: =D22/((D23+C23)/2) -> 0.67999412 | E25: =E22/((E23+D23)/2) -> 0.89810689 | F25: =F22/((F23+E23)/2) -> 0.66738192 | G25: =G22/((G23+F23)/2) -> 0.48840022 | H25: =H22/((H23+G23)/2) -> 0.53094296 | I25: =I22/((I23+H23)/2) -> 0.53726223 | J25: =J22/((J23+I23)/2) -> 0.59985699 | K25: =K22/((K23+J23)/2) -> 0.58882671 | L25: =L22/((L23+K23)/2) -> 0.54512735 | N25: =N22/((N23+L23)/2) -> 0.44673538 | O25: =O22/((O23+N23)/2) -> 0.42364287 | P25: =P22/((P23+O23)/2) -> 0.42005729 | Q25: =Q22/((Q23+P23)/2) -> 0.4200644 | R25: =R22/((R23+Q23)/2) -> 0.42007159 | S25: =S22/((S23+R23)/2) -> 0.43483753 | T25: =T22/((T23+S23)/2) -> 0.45980496 | U25: =U22/((U23+T23)/2) -> 0.47623756 | V25: =V22/((V23+U23)/2) -> 0.49323051 | W25: =W22/((W23+V23)/2) -> 0.50118656
A26: Reinvestment | C26: =C23-B23 -> 877883 | D26: =D23-C23 -> -114942 | E26: =E23-D23 -> 277269 | F26: =F23-E23 -> 114118 | G26: =G23-F23 -> 368214 | H26: =H23-G23 -> 193384 | I26: =I23-H23 -> 212044 | J26: =J23-I23 -> 375869 | ... L26: =L23-K23 -> 247958 | N26: =N22*N27 -> 452547.09 | O26: =O22*O27 -> 520036.93 | P26: =P22*P27 -> 495400.91 | Q26: =Q22*Q27 -> 551799.12 | R26: =R22*R27 -> 614642.34 | S26: =S22*S27 -> 592418.74 | T26: =T22*T27 -> 521681.98 | U26: =U22*U27 -> 431260.37 | ... W26: =W22*W27 -> 207734.72
A27: Reinvestment Rate | C27: =C26/C22 -> 2.5329332 | D27: =D26/D22 -> -0.20603528 | E27: =E26/E22 -> 0.34242951 | F27: =F26/F22 -> 0.15583557 | G27: =G26/G22 -> 0.56328367 | H27: =H26/H22 -> 0.22493812 | I27: =I26/I22 -> 0.21662257 | J27: =J26/J22 -> 0.29613703 | ... L27: =L26/L22 -> 0.15163464 | N27: =N5/N25 -> 0.29929742 | O27: =O5/O25 -> 0.31562149 | P27: =P5/P25 -> 0.27003847 | Q27: =Q5/Q25 -> 0.27012871 | R27: =R5/R25 -> 0.27021996 | S27: =S5/S25 -> 0.23008352 | T27: =T5/T25 -> 0.1796642 | U27: =U5/U25 -> 0.13671054 | ... W27: =W5/W25 -> 0.05985795
A28: D&A | B28: 275000 | C28: 248000 | D28: 261000 | E28: 802944 | F28: 875364 | G28: 426637 | H28: 455989 | I28: 546225 | J28: ='Cash Flow Statement'!D5 -> 662305 | K28: ='Cash Flow Statement'!C5 -> 666777 | L28: ='Cash Flow Statement'!B5 -> 661937 | N28: =N4*N29 -> 1001961.7 | O28: =O4*O29 -> 1135934.7 | P28: =P4*P29 -> 1264785.7 | Q28: =Q4*Q29 -> 1408302.7 | R28: =R4*R29 -> 1568161.6 | S28: =S4*S29 -> 1725054.5 | T28: =T4*T29 -> 1867562.1 | U28: =U4*U29 -> 1989152.9 | ... W28: =W4*W29 -> 2146271.7
A29: D&A (% of Revenue) | B29: =B28/B4 -> 0.096355992 | C29: =C28/C4 -> 0.079871176 | D29: =D28/D4 -> 0.076382792 | E29: =E28/E4 -> 0.23475691 | F29: =F28/F4 -> 0.23240071 | G29: =G28/G4 -> 0.12331298 | H29: =H28/H4 -> 0.10676664 | I29: =I28/I4 -> 0.1072027 | ... L29: =L28/L4 -> 0.09263343 | N29: =AVERAGE($B$29:$L$29) -> 0.12368056 | O29: =AVERAGE($B$29:$L$29) -> 0.12368056 | P29: =AVERAGE($B$29:$L$29) -> 0.12368056 | Q29: =AVERAGE($B$29:$L$29) -> 0.12368056 | R29: =AVERAGE($B$29:$L$29) -> 0.12368056 | S29: =AVERAGE($B$29:$L$29) -> 0.12368056 | T29: =AVERAGE($B$29:$L$29) -> 0.12368056 | U29: =AVERAGE($B$29:$L$29) -> 0.12368056 | ... W29: =AVERAGE($B$29:$L$29) -> 0.12368056
A30: CapEx | B30: 356000 | C30: 342000 | D30: 392000 | E30: 639000 | F30: 706000 | G30: 734000 | H30: 750000 | I30: 824000 | J30: 911000 | K30: =-SUM('Cash Flow Statement'!C20:C21) -> 989151 | L30: =-SUM('Cash Flow Statement'!B20:B21) -> 943186
A31: CapEx (% of Revenue) | B31: =B30/B4 -> 0.12473721 | C31: =C30/C4 -> 0.11014493 | D31: =D30/D4 -> 0.11472052 | E31: =E30/E4 -> 0.18682457 | F31: =F30/F4 -> 0.1874362 | G31: =G30/G4 -> 0.2121516 | H31: =H30/H4 -> 0.17560726 | I31: =I30/I4 -> 0.16171912 | ... L31: =L30/L4 -> 0.13199225
A32: NWC | C32: ='Balance Sheet'!K17-'Balance Sheet'!K30 -> -145794 | D32: ='Balance Sheet'!J17-'Balance Sheet'!J30 -> -387775 | E32: ='Balance Sheet'!I17-'Balance Sheet'!I30 -> -456137 | F32: ='Balance Sheet'!H17-'Balance Sheet'!H30 -> -753262 | G32: ='Balance Sheet'!G17-'Balance Sheet'!G30 -> -683378 | H32: ='Balance Sheet'!F17-'Balance Sheet'!F30 -> -775412 | I32: ='Balance Sheet'!E17-'Balance Sheet'!E30 -> -837243 | J32: ='Balance Sheet'!D17-'Balance Sheet'!D30 -> -691060 | K32: ='Balance Sheet'!C17-'Balance Sheet'!C30 -> -498700 | L32: ='Balance Sheet'!B17-'Balance Sheet'!B30 -> -572642 | N32: =N33*N4 -> -1246581.4 | O32: =O33*O4 -> -1413262.8 | P32: =P33*P4 -> -1573571.5 | Q32: =Q33*Q4 -> -1752127 | R32: =R33*R4 -> -1951013.9 | S32: =S33*S4 -> -1932920.5 | T32: =T33*T4 -> -1861689.7 | U32: =U33*U4 -> -1736954 | ... W32: =W33*W4 -> -1343410.8
A33: NWC (% of Revenue) | C33: =C32/C4 -> -0.046954589 | D33: =D32/D4 -> -0.11348405 | E33: =E32/E4 -> -0.13336087 | F33: =F32/F4 -> -0.19998381 | G33: =G32/G4 -> -0.19752008 | H33: =H32/H4 -> -0.1815573 | I33: =I32/I4 -> -0.16431821 | J33: =J32/J4 -> -0.11575261 | ... L33: =L32/L4 -> -0.080137222 | N33: =AVERAGE($H$33:$J$33) -> -0.15387604 | O33: =AVERAGE($H$33:$J$33) -> -0.15387604 | P33: =AVERAGE($H$33:$J$33) -> -0.15387604 | Q33: =AVERAGE($H$33:$J$33) -> -0.15387604 | R33: =AVERAGE($H$33:$J$33) -> -0.15387604 | S33: =R33-(($R$33-$W$33)/5) -> -0.13858385 | T33: =S33-(($R$33-$W$33)/5) -> -0.12329166 | U33: =T33-(($R$33-$W$33)/5) -> -0.10799947 | V33: =U33-(($R$33-$W$33)/5) -> -0.092707275 | W33: =AVERAGE(K33:L33) -> -0.077415084
A34: Change in NWC | D34: =D32-C32 -> -241981 | E34: =E32-D32 -> -68362 | F34: =F32-E32 -> -297125 | G34: =G32-F32 -> 69884 | H34: =H32-G32 -> -92034 | I34: =I32-H32 -> -61831 | J34: =J32-I32 -> 146183 | K34: =K32-J32 -> 192360 | L34: =L32-K32 -> -73942 | N34: =N32-L32 -> -673939.41 | O34: =O32-N32 -> -166681.39 | P34: =P32-O32 -> -160308.7 | Q34: =Q32-P32 -> -178555.45 | R34: =R32-Q32 -> -198886.95 | S34: =S32-R32 -> 18093.404 | T34: =T32-S32 -> 71230.799 | U34: =U32-T32 -> 124735.66 | V34: =V32-U32 -> 175030.27 | W34: =W32-V32 -> 218512.98
A35: Change in NWC (% of Revenue) | D35: =D34/D4 -> -0.070816798 | E35: =E34/E4 -> -0.019987013 | F35: =F34/F4 -> -0.078883825 | G35: =G34/G4 -> 0.020198914 | H35: =H34/H4 -> -0.021549118 | I35: =I34/I4 -> -0.012135018 | J35: =J34/J4 -> 0.024485666 | K35: =K34/K4 -> 0.028810778 | L35: =L34/L4 -> -0.010347663 | N35: =N34/N4 -> -0.083190017 | O35: =O34/O4 -> -0.018148268 | P35: =P34/P4 -> -0.015676229 | Q35: =Q34/Q4 -> -0.015681173 | R35: =R34/R4 -> -0.015686171 | S35: =S34/S4 -> 0.0012972358 | T35: =T34/T4 -> 0.0047173078 | U35: =U34/U4 -> 0.007755752 | ... W35: =W34/W4 -> 0.01259198
A36: FCFF | B36: =B22+B28-B30-B34 -> 142531.03 | C36: =C22+C28-C30-C34 -> 252587.5 | D36: =D22+D28-D30-D34 -> 668856.34 | E36: =E22+E28-E30-E34 -> 1042017.2 | F36: =F22+F28-F30-F34 -> 1198786.5 | G36: =G22+G28-G30-G34 -> 276444.95 | H36: =H22+H28-H30-H34 -> 657743.9 | I36: =I22+I28-I30-I34 -> 762919.84 | ... L36: =L22+L28-L30-L34 -> 1427926.2 | N36: =N22-N26 -> 1059484.3 | O36: =O22-O26 -> 1127623.1 | P36: =P22-P26 -> 1339155.9 | Q36: =Q22-Q26 -> 1490927.5 | R36: =R22-R26 -> 1659957.8 | S36: =S22-S26 -> 1982379.9 | T36: =T22-T26 -> 2381968.1 | U36: =U22-U26 -> 2723290.7 | ... W36: =W22-W26 -> 3262727
A37: PV(FCFF) | N37: =N36/(1+$Z$16)^1 -> 978403.22 | O37: =O36/(1+$Z$16)^2 -> 961635.94 | P37: =P36/(1+$Z$16)^3 -> 1054632.6 | Q37: =Q36/(1+$Z$16)^4 -> 1084301.2 | R37: =R36/(1+$Z$16)^5 -> 1114843.2 | S37: =S36/(1+$Z$16)^6 -> 1229495.7 | T37: =T36/(1+$Z$16)^7 -> 1364267.1 | U37: =U36/(1+$Z$16)^7 -> 1559758.9 | V37: =V36/(1+$Z$16)^7 -> 1743719.2 | W37: =W36/(1+$Z$16)^7 -> 1868719.9
A38: Terminal Value | W38: =(W36*(1+Z15))/(Z16-Z15) -> 63562648
A39: PV(TV) | W39: =W38/(1+Z16)^10 -> 28670516
A40: Enterprise Value | W40: =SUM(N37:W37,W39) -> 41630293
...
